Workbook

Sheet Responses
A1: Id | B1: Start time | C1: Completion time | D1: Email | E1: Name | F1: Full legal name as per your AWS Certificate | G1: Intuitive email address | H1: Which AWS certifications have you completed? | I1: Certification level | J1: Certification date | K1: Certification expiry date | L1: Which AWS certifications have you completed?1 | M1: Practice | N1: Practice Director | O1: Geography | P1: Which describes your AWS certification account today? | Q1: Personal email holding your certifications | R1: AWS Certification Candidate ID | S1: Have you given consent in AWS Skill Builder to share your certifications with the company? | T1: Candidate ID on your second account | U1: Certification account email changed to Intuitive? | V1: Partner Central Training and Certification email updated? | W1: AWS merge case raised? | X1: AWS support case number | Y1: Partner Alliance contacted for a new invitation? | Z1: What you are unsure about
A2: 3 | B2: 46241.99 | C2: 46241.994 | D2: Ampil.Verma@intuitive.AI | E2: Ampil Verma | F2: Ampil Verma | G2: ampil.verma@intuitive.ai | I2: Associate | L2: AWS Certified Cloud Practitioner | P2: A - Certifications under a personal email only | S2: No, not yet | U2: Not started
A3: 4 | B3: 46241.998 | C3: 46242 | D3: Aditya.Desai@intuitive.AI | E3: Aditya Desai | F3: Aditya Desai | G3: aditya.desai@intuitive.ai | I3: Foundation | L3: AWS Certified Cloud Practitioner | P3: B - Already under Intuitive email and associated in Partner Central | R3: AWS05675016 | S3: Yes, consent given
A4: 5 | B4: 46242.027 | C4: 46242.03 | D4: Harsh.Kharwar@intuitive.AI | E4: Harsh Kharwar | F4: Harsh Kharwar | G4: harsh.kharwar@intuitive.ai | I4: Foundation | L4: AWS Certified Cloud Practitioner | P4: B - Already under Intuitive email and associated in Partner Central | R4: AWS05696884 | S4: Yes, consent given
A5: 6 | B5: 46242.026 | C5: 46242.031 | D5: Het.Shah@intuitive.AI | E5: Het Shah | F5: Het Shah | G5: Het.shah@intuitive.ai | I5: Associate;Professional | L5: AWS Certified Solutions Architect – Associate;AWS Certified Solutions Architect – Professional | P5: B - Already under Intuitive email and associated in Partner Central | R5: AWS05850512 | S5: Yes, consent given
A6: 7 | B6: 46242.027 | C6: 46242.034 | D6: Gourab.Banerjee@Intuitive.AI | E6: Gourab Banerjee | F6: Gourab Banerjee | G6: gourab.banerjee@intuitive.ai | I6: Foundation | L6: AWS Certified Cloud Practitioner | P6: A - Certifications under a personal email only | Q6: gourabbanerjee1994@gmail.com | R6: AWS05211917 | S6: Yes, consent given | T6: AWS06166624 | U6: Blocked
A7: 8 | B7: 46242.026 | C7: 46242.035 | D7: Kenil.Sarang@intuitive.AI | E7: Kenil Sarang | F7: Kenil Sarang | G7: kenil.sarang@intuitive.ai | I7: Foundation | L7: AWS Certified Cloud Practitioner | P7: B - Already under Intuitive email and associated in Partner Central | R7: AWS05692298 | S7: Yes, consent given
A8: 9 | B8: 46242.026 | C8: 46242.042 | D8: Jigarkumar.Bhoye@intuitive.AI | E8: Jigarkumar Bhoye | F8: Jigarkumar Bhoye | G8: jigarkumar.bhoye@intuitive.ai | I8: Foundation;Associate | L8: AWS Certified Cloud Practitioner;AWS Certified Solutions Architect – Associate | P8: B - Already under Intuitive email and associated in Partner Central | R8: AWS05710653 | S8: Yes, consent given
A9: 10 | B9: 46242.051 | C9: 46242.054 | D9: peter.turner@intuitive.ai | E9: Peter Turner | F9: Peter Turner | G9: peter.turner@intuitive.ai | I9: Associate | L9: AWS Certified Developer – Associate;AWS Certified Solutions Architect – Associate | P9: B - Already under Intuitive email and associated in Partner Central | Q9: syntax.valid@gmail.com | R9: AWS02917840 | S9: Yes, consent given | U9: Completed
A10: 11 | B10: 46242.047 | C10: 46242.056 | D10: Parth.Vadodaria@intuitive.AI | E10: Parth Vadodaria | F10: Parth Vadodaria | G10: parth.vadodaria@intuitive.ai | I10: Foundation | L10: AWS Certified Cloud Practitioner | P10: B - Already under Intuitive email and associated in Partner Central | R10: AWS05696846 | S10: Yes, consent given
A11: 12 | B11: 46242.051 | C11: 46242.065 | D11: Liang.Ren@intuitive.AI | E11: Liang Ren | F11: Liang Ren | G11: liang.ren@intuitive.ai | I11: Specialty | L11: AWS Certified Security – Specialty | P11: A - Certifications under a personal email only | Q11: liang.ren.ca@gmail.com | R11: 9436c9415f744791999e245377a7ac56 | S11: No, not yet | U11: Not started
A12: 13 | B12: 46242.036 | C12: 46242.067 | D12: Dhairya.S@intuitive.AI | E12: Dhairya S | F12: Dhairya Shah | G12: dhairya.s@intuitive.ai | I12: Foundation;Associate | L12: AWS Certified Cloud Practitioner;AWS Certified AI Practitioner;AWS Certified Solutions Architect – Associate;AWS Certified Developer – Associate | P12: A - Certifications under a personal email only | Q12: hello@dhairyashah.dev | R12: AWS05683097 | S12: Yes, consent given | U12: Completed
A13: 14 | B13: 46242.04 | C13: 46242.07 | D13: Khushi.Carpenter@intuitive.ai | E13: Khushi Carpenter | F13: Khushi Carpenter | G13: khushi.carpenter@intuitive.ai | I13: Foundation;Associate;Professional | L13: AWS Certified Cloud Practitioner;AWS Certified Solutions Architect – Associate;AWS Certified Solutions Architect – Professional | P13: B - Already under Intuitive email and associated in Partner Central | S13: Yes, consent given | U13: Completed
A14: 15 | B14: 46242.078 | C14: 46242.082 | D14: vishal.kanade@intuitive.ai | E14: Vishal Kanade | F14: Vishal Kanade | G14: vishal.kanade@intuitive.ai | I14: Associate | L14: AWS Certified AI Practitioner;AWS Certified Solutions Architect – Associate;AWS Certified Data Engineer – Associate | P14: A - Certifications under a personal email only | Q14: vishalkanade700@gmail.com | S14: Yes, consent given | U14: Completed
A15: 16 | B15: 46242.389 | C15: 46242.393 | D15: Hari.Baskar@intuitive.ai | E15: Hari Baskar | F15: Haribaskar D | G15: hari.baskar@intuitive.ai | I15: Associate | L15: AWS Certified Solutions Architect – Associate | P15: A - Certifications under a personal email only | R15: c108eea016724f08a1c2f02b5b36e0b8 | S15: No, not yet | T15: c108eea016724f08a1c2f02b5b36e0b8 | U15: Not started
A16: 17 | B16: 46242.422 | C16: 46242.429 | D16: Nicolas.David@intuitive.AI | E16: Nicolas David | F16: Nicolas Benjamin David | G16: nicolas.david@intuitive.ai | I16: Foundation;Associate;Professional;Specialty | L16: AWS Certified AI Practitioner;AWS Certified Solutions Architect – Associate;AWS Certified Developer – Associate;AWS Certified Solutions Architect – Professional;AWS Certified DevOps Engineer – Professional;AWS Certified Security – Specialty;AWS Certified CloudOps Engineer – Associate;Other (Please specify) | P16: A - Certifications under a personal email only | Q16: nicolas.david@anamor.ph | S16: Yes, consent given | U16: Not started
A17: 18 | B17: 46242.351 | C17: 46242.434 | D17: Arvind.Raj@Intuitive.AI | E17: Arvind Raj | F17: Arvind Raj | G17: arvind.raj@intuitive.ai | I17: Associate | L17: AWS Certified Solutions Architect – Associate | P17: A - Certifications under a personal email only | Q17: arvindraj3650@gmail.com | R17: 7589eaa5c7674f9ea7ebcdc5051b2199 | S17: Yes, consent given | T17: AWS03645046 | U17: Completed
A18: 19 | B18: 46242.755 | C18: 46242.811 | D18: Poojan.Soni@intuitive.ai | E18: Poojan Soni | F18: Poojan Pritin Soni | G18: poojan.soni@intuitive.ai | I18: Foundation;Associate | L18: AWS Certified Cloud Practitioner;AWS Certified Solutions Architect – Associate | P18: B - Already under Intuitive email and associated in Partner Central | S18: Yes, consent given | U18: Completed
A19: 20 | B19: 46243.981 | C19: 46243.995 | D19: Sanjay.Kulgod@intuitive.AI | E19: Sanjay Kulgod | F19: Sanjay Kulgod | G19: sanjay.kulgod@intuitive.ai | I19: Professional | L19: AWS Certified Cloud Practitioner;AWS Certified Solutions Architect – Associate;AWS Certified Solutions Architect – Professional | P19: A - Certifications under a personal email only | Q19: skulgod@yahoo.com | S19: Yes, consent given | T19: 483223797 (exm Id - Solution Sarch Prof - have the badge) | U19: Completed
A20: 21 | B20: 46244.347 | C20: 46244.394 | D20: Girish.VenkataReddy@intuitive.ai | E20: Girish VenkataReddy | F20: Girish Venkata Reddy | G20: girish.venkatareddy@intuitive.ai | I20: Foundation | L20: AWS Certified Cloud Practitioner | P20: A - Certifications under a personal email only | Q20: venkatareddygirish@gmail.com | R20: AWS04058060 | S20: No, not yet | T20: AWS04058060 | U20: Not started
A21: 22 | B21: 46244.528 | C21: 46244.529 | D21: Sri.Kiran@intuitive.AI | E21: Sri Kiran | F21: Sri Kiran Kanchibhotla | G21: sri.kiran@intuitive.ai | I21: Foundation | L21: Other (Please specify) | P21: B - Already under Intuitive email and associated in Partner Central | S21: Yes, consent given | U21: Completed
A22: 23 | B22: 46244.575 | C22: 46244.58 | D22: suyash.srivastava@Intuitive.AI | E22: Suyansh Srivastava | F22: Suyash Srivastava | G22: suyash.srivastava@intuitive.ai | I22: Foundation | L22: AWS Certified Cloud Practitioner | P22: B - Already under Intuitive email and associated in Partner Central | S22: Yes, consent given
A23: 24 | B23: 46244.594 | C23: 46244.612 | D23: Vishal.Mehta@intuitive.AI | E23: Vishal Mehta | F23: Vishal Mehta | G23: vishal.mehta@intuitive.ai | I23: Foundation | L23: AWS Certified AI Practitioner | P23: B - Already under Intuitive email and associated in Partner Central | R23: AWS05712822 | S23: Yes, consent given | U23: Completed
A24: 25 | B24: 46244.597 | C24: 46244.688 | D24: Bhumi.Patel@intuitive.AI | E24: Bhumi Patel | F24: Bhumi Patel | G24: bhumi.patel@intuitive.ai | I24: Foundation | L24: AWS Certified AI Practitioner | P24: B - Already under Intuitive email and associated in Partner Central | R24: AWS05692396 | S24: Yes, consent given | U24: Completed
A25: 26 | B25: 46244.681 | C25: 46244.69 | D25: Yuktha.Pulukkul@intuitive.AI | E25: Yuktha Pulukkul | F25: Yuktha Pulukkul | G25: yuktha.pulukkul@intuitive.ai | I25: Foundation | L25: AWS Certified Cloud Practitioner | P25: B - Already under Intuitive email and associated in Partner Central | R25: AWS05710195 | S25: Yes, consent given | U25: Completed
A26: 27 | B26: 46244.715 | C26: 46244.719 | D26: Rushi.Kardani@intuitive.AI | E26: Rushi Kardani | F26: Rushi Kardani | G26: rushi.kardani@intuitive.ai | I26: Foundation | L26: AWS Certified Cloud Practitioner | P26: B - Already under Intuitive email and associated in Partner Central | R26: AWS05692236 | S26: Yes, consent given | U26: Completed
A27: 28 | B27: 46244.728 | C27: 46244.729 | D27: vanshika.bhatia@intuitive.ai | E27: Vanshika Bhatia | F27: Vanshika Bhatia | G27: vanshika.bhatia@intuitive.ai | I27: Foundation | L27: AWS Certified Cloud Practitioner | P27: B - Already under Intuitive email and associated in Partner Central | S27: Yes, consent given
A28: 29 | B28: 46244.725 | C28: 46244.73 | D28: Dhruvi.Soni@intuitive.AI | E28: Dhruvi Soni | F28: Dhruvi Soni | G28: dhruvi.soni@intuitive.ai | I28: Foundation | L28: AWS Certified Cloud Practitioner | P28: B - Already under Intuitive email and associated in Partner Central | S28: Yes, consent given
A29: 30 | B29: 46244.718 | C29: 46244.734 | D29: Faraaz.Bhojawala@intuitive.AI | E29: Faraaz Bhojawala | F29: Faraaz Bhojawala | G29: faraaz.bhojawala@intuitive.ai | I29: Foundation | L29: AWS Certified Cloud Practitioner | P29: B - Already under Intuitive email and associated in Partner Central | R29: AWS06121572 | S29: Yes, consent given | U29: Completed
A30: 31 | B30: 46244.718 | C30: 46244.734 | D30: Dhruvam.Tandel@intuitive.AI | E30: Dhruvam Tandel | F30: Dhruvam Tandel | G30: dhruvam.tandel@intuitive.AI | I30: Foundation | L30: AWS Certified Cloud Practitioner | P30: B - Already under Intuitive email and associated in Partner Central | R30: AWS06121567 | S30: Yes, consent given | U30: Completed
A31: 32 | B31: 46244.735 | C31: 46244.736 | D31: Anmol.Purohit@intuitive.AI | E31: Anmol Purohit | F31: Anmol Purohit | G31: anmol.purohit@intuitive.ai | I31: Foundation | L31: AWS Certified Cloud Practitioner | P31: B - Already under Intuitive email and associated in Partner Central | S31: Yes, consent given | U31: Completed
A32: 33 | B32: 46244.726 | C32: 46244.736 | D32: Chaitanya.Baweja@intuitive.AI | E32: Chaitanya Baweja | F32: Chaitanya Baweja | G32: Chaitanya.Baweja@intuitive.AI | I32: Foundation | L32: AWS Certified Cloud Practitioner | P32: B - Already under Intuitive email and associated in Partner Central | R32: AWS05710205 | S32: Yes, consent given | U32: Completed
A33: 34 | B33: 46244.736 | C33: 46244.751 | D33: Dhruv.Maradiya@intuitive.AI | E33: Dhruv Maradiya | F33: Dhruv Maradiya | G33: dhruv.maradiya@intuitive.ai | I33: Associate | L33: AWS Certified Solutions Architect – Associate | P33: A - Certifications under a personal email only | Q33: dhruvmvr@gmail.com | R33: AWS05355328 | S33: No, not yet | U33: Not started
A34: 35 | B34: 46244.748 | C34: 46244.752 | D34: Sahal.Pathan@intuitive.AI | E34: Sahal Pathan | F34: Mohmed Sahal Pathan | G34: sahal.pathan@intuitive.ai | I34: Associate | L34: AWS Certified Solutions Architect – Associate | P34: A - Certifications under a personal email only | Q34: sahalpathan5601@gmail.com | R34: AWS04682992 | S34: No, not yet | U34: Not started
A35: 36 | B35: 46244.716 | C35: 46244.766 | D35: Satvik.Sharma@intuitive.AI | E35: Satvik Sharma | F35: Satvik Sharma | G35: satvik.sharma@intuitive.ai | I35: Foundation | L35: AWS Certified Cloud Practitioner | P35: B - Already under Intuitive email and associated in Partner Central | S35: Yes, consent given | U35: Completed
A36: 37 | B36: 46244.765 | C36: 46244.768 | D36: Malhar.Prajapati@intuitive.AI | E36: Malhar Prajapati | F36: Malhar Prajapati | G36: malhar.prajapati@intuitive.ai | I36: Foundation | L36: AWS Certified AI Practitioner | P36: B - Already under Intuitive email and associated in Partner Central | S36: Yes, consent given
A37: 38 | B37: 46244.758 | C37: 46244.773 | D37: Smit.Gandhi@intuitive.AI | E37: Smit Gandhi | F37: Smit Gandhi | G37: smit.gandhi@intuitive.ai | I37: Foundation | L37: AWS Certified AI Practitioner | P37: B - Already under Intuitive email and associated in Partner Central | Q37: smitgandhi585@gmail.com | R37: AWS05674996 | S37: Yes, consent given | U37: Completed
A38: 39 | B38: 46244.757 | C38: 46244.786 | D38: Prachi.Desai@intuitive.AI | E38: Prachi Desai | F38: Prachi Desai | G38: prachi.desai@intuitive.ai | I38: Foundation | L38: AWS Certified AI Practitioner | P38: B - Already under Intuitive email and associated in Partner Central | Q38: prachidesai7708@gmail.com | R38: AWS05692267 | S38: Yes, consent given | U38: Completed
A39: 40 | B39: 46244.797 | C39: 46244.8 | D39: Tulika.Aggarwal@intuitive.AI | E39: Tulika Aggarwal | F39: Tulika Aggarwal | G39: tulika.aggarwal@intuitive.ai | I39: Associate | L39: AWS Certified Data Engineer – Associate | P39: A - Certifications under a personal email only | Q39: tulikaaggarwal07@gmail.com | R39: 4eb1f1edc7d3459389c0f8318db23d4d | S39: Yes, consent given | U39: Not started
A40: 41 | B40: 46244.825 | C40: 46244.84 | D40: Sachit.Desai@intuitive.ai | E40: Sachit Desai | F40: Sachit Desai | G40: sachit.desai@intuitive.cloud | I40: Foundation;Associate | L40: AWS Certified Cloud Practitioner;AWS Certified Solutions Architect – Associate | P40: B - Already under Intuitive email and associated in Partner Central | R40: AWS04946597 | S40: Yes, consent given | U40: Completed
...

Sheet Certification Register
A1: AWS Certification Register
A2: One row per certification holder | 115 certification records from 67 responses
A4: Person | B4: Certification Level | C4: Certification Name | D4: Total Certifications Held | E4: Certifications at This Level | F4: Skill Builder Consent
A5: Bhumi Patel | B5: Foundation | C5: AWS Certified AI Practitioner | D5: =COUNTIF($A$5:$A$119,A5) -> 1 | E5: =COUNTIFS($A$5:$A$119,A5,$B$5:$B$119,B5) -> 1 | F5: Yes, consent given
A6: Dhairya Shah | B6: Foundation | C6: AWS Certified AI Practitioner | D6: =COUNTIF($A$5:$A$119,A6) -> 4 | E6: =COUNTIFS($A$5:$A$119,A6,$B$5:$B$119,B6) -> 2 | F6: Yes, consent given
A7: Honey Agarwal | B7: Foundation | C7: AWS Certified AI Practitioner | D7: =COUNTIF($A$5:$A$119,A7) -> 2 | E7: =COUNTIFS($A$5:$A$119,A7,$B$5:$B$119,B7) -> 2 | F7: Yes, consent given
A8: ISMAIL TAHER RAJA | B8: Foundation | C8: AWS Certified AI Practitioner | D8: =COUNTIF($A$5:$A$119,A8) -> 4 | E8: =COUNTIFS($A$5:$A$119,A8,$B$5:$B$119,B8) -> 2 | F8: Yes, consent given
A9: Malhar Prajapati | B9: Foundation | C9: AWS Certified AI Practitioner | D9: =COUNTIF($A$5:$A$119,A9) -> 1 | E9: =COUNTIFS($A$5:$A$119,A9,$B$5:$B$119,B9) -> 1 | F9: Yes, consent given
A10: Nicolas Benjamin David | B10: Foundation | C10: AWS Certified AI Practitioner | D10: =COUNTIF($A$5:$A$119,A10) -> 8 | E10: =COUNTIFS($A$5:$A$119,A10,$B$5:$B$119,B10) -> 1 | F10: Yes, consent given
A11: Prachi Desai | B11: Foundation | C11: AWS Certified AI Practitioner | D11: =COUNTIF($A$5:$A$119,A11) -> 1 | E11: =COUNTIFS($A$5:$A$119,A11,$B$5:$B$119,B11) -> 1 | F11: Yes, consent given
A12: Smit Gandhi | B12: Foundation | C12: AWS Certified AI Practitioner | D12: =COUNTIF($A$5:$A$119,A12) -> 1 | E12: =COUNTIFS($A$5:$A$119,A12,$B$5:$B$119,B12) -> 1 | F12: Yes, consent given
A13: Vishal Kanade | B13: Foundation | C13: AWS Certified AI Practitioner | D13: =COUNTIF($A$5:$A$119,A13) -> 3 | E13: =COUNTIFS($A$5:$A$119,A13,$B$5:$B$119,B13) -> 1 | F13: Yes, consent given
A14: Vishal Mehta | B14: Foundation | C14: AWS Certified AI Practitioner | D14: =COUNTIF($A$5:$A$119,A14) -> 1 | E14: =COUNTIFS($A$5:$A$119,A14,$B$5:$B$119,B14) -> 1 | F14: Yes, consent given
A15: Aditya Desai | B15: Foundation | C15: AWS Certified Cloud Practitioner | D15: =COUNTIF($A$5:$A$119,A15) -> 1 | E15: =COUNTIFS($A$5:$A$119,A15,$B$5:$B$119,B15) -> 1 | F15: Yes, consent given
A16: Aditya Prabhune | B16: Foundation | C16: AWS Certified Cloud Practitioner | D16: =COUNTIF($A$5:$A$119,A16) -> 1 | E16: =COUNTIFS($A$5:$A$119,A16,$B$5:$B$119,B16) -> 1 | F16: Yes, consent given
... A119: Sunil Kumar Bhagat | B119: Other / Unspecified | C119: Other (Please specify) | D119: =COUNTIF($A$5:$A$119,A119) -> 7 | E119: =COUNTIFS($A$5:$A$119,A119,$B$5:$B$119,B119) -> 1 | F119: Yes, consent given

Sheet Dashboard
D1: AWS Certification Dashboard
D2: Complete counts by certification, level, and Skill Builder consent
D4: PEOPLE | G4: CERTIFICATIONS | J4: CERTIFICATION TYPES | M4: CONSENT RATE
D5: =COUNTA(Responses!$F$2:$F$70) -> 69 | G5: =COUNTA('Certification Register'!$C$5:$C$119) -> 115 | J5: {=COUNTA(_xlfn.UNIQUE(_xlfn._xlws.FILTER('Certification Register'!$C$5:$C$119,'Certification Register'!$C$5:$C$119<>"")))} -> 13 | M5: =COUNTIF(Responses!$S$2:$S$70,"Yes*")/COUNTA(Responses!$F$2:$F$70) -> 0.79710145
D6: employees reporting certifications | G6: person–certification records | J6: distinct certification names | M6: people who gave consent
D8: KEY FINDINGS
D9: ="The workbook contains "&TEXT(G5,"#,##0")&" certification records across "&TEXT(D5,"#,##0")&" people and "&TEXT(J5,"#,##0")&" certification names. Foundation and Associate credentials account for "&TEXT((COUNTIF('Certification Register'!$B$5:$B$119,"Foundation")+COUNTIF('Certification Register'!$B$5:$B$119,"Associate"))/G5,"0.0%")&" of all records. Skill Builder consent has been provided by "&TEXT(M5,"0.0%")&" of respondents. Counts below remain linked to the register and response sheets." -> The workbook contains 115 certification records across 69 people and 13 certification names. Foundation and Associate credentials account for 82.6% of all records. Skill Builder consent has been provided by 79.7% of respondents. Counts below remain linked to the register and response sheets.
D13: COUNT BY CERTIFICATION LEVEL | J13: COUNT BY SKILL BUILDER CONSENT
D14: Certification Level | E14: Count | J14: Consent Status | K14: People | L14: Certification Records
D15: Foundation | E15: =COUNTIF('Certification Register'!$B$5:$B$119,D15) -> 56 | J15: Yes, consent given | K15: =COUNTIF(Responses!$S$2:$S$70,J15) -> 55 | L15: =COUNTIF('Certification Register'!$F$5:$F$119,J15) -> 96
D16: Associate | E16: =COUNTIF('Certification Register'!$B$5:$B$119,D16) -> 39 | J16: No, not yet | K16: =COUNTIF(Responses!$S$2:$S$70,J16) -> 14 | L16: =COUNTIF('Certification Register'!$F$5:$F$119,J16) -> 19
D17: Professional | E17: =COUNTIF('Certification Register'!$B$5:$B$119,D17) -> 12 | J17: Total | K17: =SUM(K15:K16) -> 69 | L17: =SUM(L15:L16) -> 115
D18: Specialty | E18: =COUNTIF('Certification Register'!$B$5:$B$119,D18) -> 6
D19: Other / Unspecified | E19: =COUNTIF('Certification Register'!$B$5:$B$119,D19) -> 2
D20: Total | E20: =SUM(E15:E19) -> 115
D23: COUNT BY CERTIFICATION NAME
D24: Certification Name | E24: Level | F24: Count
D25: AWS Certified AI Practitioner | E25: Foundation | F25: =COUNTIF('Certification Register'!$C$5:$C$119,D25) -> 10
D26: AWS Certified Cloud Practitioner | E26: Foundation | F26: =COUNTIF('Certification Register'!$C$5:$C$119,D26) -> 43
D27: Other (Please specify) | E27: Foundation | F27: =COUNTIF('Certification Register'!$C$5:$C$119,D27) -> 6
D28: AWS Certified CloudOps Engineer – Associate | E28: Associate | F28: =COUNTIF('Certification Register'!$C$5:$C$119,D28) -> 2
D29: AWS Certified Data Engineer – Associate | E29: Associate | F29: =COUNTIF('Certification Register'!$C$5:$C$119,D29) -> 3
D30: AWS Certified Developer – Associate | E30: Associate | F30: =COUNTIF('Certification Register'!$C$5:$C$119,D30) -> 4
D31: AWS Certified Machine Learning Engineer – Associate | E31: Associate | F31: =COUNTIF('Certification Register'!$C$5:$C$119,D31) -> 1
D32: AWS Certified Solutions Architect – Associate | E32: Associate | F32: =COUNTIF('Certification Register'!$C$5:$C$119,D32) -> 28
D33: AWS Certified SysOps Administrator Associate | E33: Associate | F33: =COUNTIF('Certification Register'!$C$5:$C$119,D33) -> 1
D34: AWS Certified DevOps Engineer – Professional | E34: Professional | F34: =COUNTIF('Certification Register'!$C$5:$C$119,D34) -> 4
D35: AWS Certified Solutions Architect – Professional | E35: Professional | F35: =COUNTIF('Certification Register'!$C$5:$C$119,D35) -> 8
D36: AWS Certified Advanced Networking – Specialty | E36: Specialty | F36: =COUNTIF('Certification Register'!$C$5:$C$119,D36) -> 2
D37: AWS Certified Security – Specialty | E37: Specialty | F37: =COUNTIF('Certification Register'!$C$5:$C$119,D37) -> 3
D38: Total | F38: =SUM(F25:F37) -> 115
