Workbook

Sheet Certifications
A1: Name | B1: Email ID | C1: Completed | D1: Cert Type | E1: Comments | F1: Reports To | G1: Practice Director | H1: Completion Date | I1: Target Date | J1: Mandatory | K1: Voluntary | L1: Employee Status | M1: Comment | N1: Registered in DBX partner portal | O1: Databricks x check
A2: Keval Hingu | B2: Keval.Hingu@intuitive.cloud | C2: Completed | D2: Databricks Certified Data Analyst Associate | E2: Completed on 20th May 2025 | F2: Lucian Cimpeanu (Cloud Engineering) | G2: Stefano Pecora (Cloud + Platform Eng) | H2: 45473 | I2: 45930 | J2: Mandatory | O2: =VLOOKUP(B2,'From Databricks partner portal'!E:E,1,FALSE) -> #N/A
A3: Abirbhaba Sahu | B3: Abirbhaba.Sahu@intuitive.cloud | C3: In-progress | F3: Mohammed Shabbir (App + DB Mod) | G3: Mohammed Shabbir (App + DB Mod) | J3: Mandatory | O3: =VLOOKUP(B3,'From Databricks partner portal'!E:E,1,FALSE) -> #N/A
A4: Prem Gandhi | B4: Prem.Gandhi@intuitive.cloud | C4: Completed | D4: Databricks Certified Machine Learning Associate | E4: Completed on 18th April, 2025 | F4: Dr Shake Mohaideen PhD (AI/MlOps) | G4: Dr Navid Kalantari PhD (Data + AI) | H4: 45765 | I4: 45930 | J4: Mandatory | O4: =VLOOKUP(B4,'From Databricks partner portal'!E:E,1,FALSE) -> #N/A
A5: Aditya Desai | B5: Aditya.Desai@intuitive.AI | C5: Completed | D5: Databricks Certified Data Analyst Associate | F5: Bhavesh Shah (Cloud Native) | G5: Bhavesh Shah (Cloud Native) | H5: 46006 | I5: 46006 | J5: Mandatory | O5: =VLOOKUP(B5,'From Databricks partner portal'!E:E,1,FALSE) -> aditya.desai@intuitive.ai
A6: Aniket Purohit | B6: Aniket.Purohit@intuitive.cloud | C6: Completed | D6: Databricks Certified Generative AI Engineer Associate | E6: Completed on 29th May, 2025 | F6: Saksham Baru (Cloud Engineering) | G6: Stefano Pecora (Cloud + Platform Eng) | H6: 45766 | I6: 45930 | J6: Mandatory | O6: =VLOOKUP(B6,'From Databricks partner portal'!E:E,1,FALSE) -> #N/A
A7: Divya Mahesh | B7: Divya.Mahesh@intuitive.cloud | C7: Completed | D7: Databricks Certified Generative AI Engineer Associate | F7: Saksham Baru (Cloud Engineering) | G7: Stefano Pecora (Cloud + Platform Eng) | H7: 45770 | I7: 45930 | J7: Mandatory | O7: =VLOOKUP(B7,'From Databricks partner portal'!E:E,1,FALSE) -> #N/A
A8: Ajay Shridhar Giri | B8: Ajay.Giri@intuitive.cloud | C8: Completed | D8: Databricks Certified Data Analyst Associate | E8: Completed on 15th June, 2025 | F8: Saksham Baru (Cloud Engineering) | G8: Stefano Pecora (Cloud + Platform Eng) | H8: 45772 | I8: 45930 | J8: Mandatory | O8: =VLOOKUP(B8,'From Databricks partner portal'!E:E,1,FALSE) -> #N/A
A9: Ajitesh Sudan | B9: Ajitesh.Sudan@intuitive.cloud | C9: In-progress | D9: Databricks Certified Generative AI Engineer Associate | F9: Saksham Baru (Cloud Engineering) | G9: Stefano Pecora (Cloud + Platform Eng) | J9: Mandatory | M9: Not cleared | O9: =VLOOKUP(B9,'From Databricks partner portal'!E:E,1,FALSE) -> #N/A
A10: Anand Akurathi | B10: anand.akurathi@intuitive.cloud | C10: In-progress | F10: Prakash Patil (App + DB Mod) | G10: Prakash Patil (App + DB Mod) | J10: Mandatory | O10: =VLOOKUP(B10,'From Databricks partner portal'!E:E,1,FALSE) -> #N/A
A11: Dinesh Verma | B11: dinesh.verma@intuitive.cloud | C11: Completed | D11: Databricks Certified Generative AI Engineer Associate | E11: Completed on 27th June, 2025 | F11: Dr Shake Mohaideen PhD (AI/MlOps) | G11: Bhavesh Shah (Cloud Native) | H11: 45773 | I11: 45930 | J11: Mandatory | O11: =VLOOKUP(B11,'From Databricks partner portal'!E:E,1,FALSE) -> #N/A
A12: Anil Amara | B12: Anil.Amara@intuitive.cloud | C12: In-progress | F12: Mohammed Shabbir (App + DB Mod) | G12: Mohammed Shabbir (App + DB Mod) | J12: Mandatory | O12: =VLOOKUP(B12,'From Databricks partner portal'!E:E,1,FALSE) -> #N/A
A13: Ankit Parekh | B13: Ankit.Parekh@intuitive.cloud | C13: In-progress | D13: Databricks Certified Generative AI Engineer Associate | F13: Saksham Baru (Cloud Engineering) | G13: Stefano Pecora (Cloud + Platform Eng) | J13: Mandatory | M13: Not cleared | O13: =VLOOKUP(B13,'From Databricks partner portal'!E:E,1,FALSE) -> #N/A
A14: Ravindra Malpute | B14: Ravindra.Malpute@intuitive.cloud | C14: Completed | D14: Databricks Certified Generative AI Engineer Associate | E14: Completed on 25th April, 2025 | F14: Piyush Jalan (Cloud Engineering) | G14: Bhavesh Shah (Cloud Native) | H14: 45784 | I14: 45930 | J14: Mandatory | O14: =VLOOKUP(B14,'From Databricks partner portal'!E:E,1,FALSE) -> #N/A
A15: Saumil Shah | B15: Saumil.Shah@intuitive.cloud | C15: Completed | D15: Databricks Certified Data Analyst Associate | E15: Completed on 19th April, 2025 | F15: Piyush Jalan (Cloud Engineering) | G15: Bhavesh Shah (Cloud Native) | H15: 45784 | I15: 45930 | J15: Mandatory | O15: =VLOOKUP(B15,'From Databricks partner portal'!E:E,1,FALSE) -> #N/A | P15: Asked to follow KB article
A16: Apratim Paul | B16: Apratim.Paul@intuitive.cloud | C16: Inactive | D16: Databricks Certified Data Engineer Associate | E16: Completed on 30th June,2025 | F16: Chett Rubenstein (Data + AI) | G16: Chett Rubenstein (Data + AI) | H16: 45807 | I16: 45930 | J16: Mandatory | L16: InActive | N16: n/a | O16: =VLOOKUP(B16,'From Databricks partner portal'!E:E,1,FALSE) -> #N/A
A17: Arnob Kumar Dey | B17: arnob.dey@intuitive.cloud | C17: Inactive | D17: Databricks Certified Data Engineer Associate | F17: Chett Rubenstein (Data + AI) | G17: Chett Rubenstein (Data + AI) | H17: 45928 | I17: 45930 | J17: Mandatory | L17: InActive | N17: n/a | O17: =VLOOKUP(B17,'From Databricks partner portal'!E:E,1,FALSE) -> #N/A
A18: Aryan Vasudev | B18: aryan.vasudev@Intuitive.AI | C18: Completed | D18: Databricks Certified Data Analyst Associate | E18: Databricks Certified Data Analyst Associate | F18: Bhavesh Shah (Cloud Native) | G18: Bhavesh Shah (Cloud Native) | H18: 45996 | I18: 45996 | J18: Mandatory | O18: =VLOOKUP(B18,'From Databricks partner portal'!E:E,1,FALSE) -> aryan.vasudev@intuitive.ai
A19: Abhijeet Patil | B19: Abhijeet.Patil@intuitive.cloud | C19: Completed | D19: Databricks Certified Data Analyst Associate | E19: Completed on 30th May, 2025 | F19: Saksham Baru (Cloud Engineering) | G19: Stefano Pecora (Cloud + Platform Eng) | H19: 45793 | I19: 45930 | J19: Mandatory | O19: =VLOOKUP(B19,'From Databricks partner portal'!E:E,1,FALSE) -> #N/A | P19: Asked to follow KB article
A20: Aziz Saidi | B20: Aziz.Saidi@intuitive.cloud | C20: In-progress | F20: Mohammed Shabbir (App + DB Mod) | G20: Mohammed Shabbir (App + DB Mod) | J20: Mandatory | O20: =VLOOKUP(B20,'From Databricks partner portal'!E:E,1,FALSE) -> #N/A
A21: Azmat Ahanger | B21: azmat.rahim@intuitive.cloud | C21: In-progress | F21: Mohammed Shabbir (App + DB Mod) | G21: Mohammed Shabbir (App + DB Mod) | J21: Mandatory | O21: =VLOOKUP(B21,'From Databricks partner portal'!E:E,1,FALSE) -> #N/A
A22: Balachandra Kandukuri | B22: balachandra.kandukuri@intuitive.cloud | C22: In-progress | F22: Dr Shake Mohaideen PhD (Data + AI) | G22: Dr Navid Kalantari PhD (Data + AI) | J22: Mandatory | O22: =VLOOKUP(B22,'From Databricks partner portal'!E:E,1,FALSE) -> #N/A
A23: Bhagesh Puri | B23: bhagesh.puri@intuitive.ai | C23: In-progress | F23: Uday Kakkar (Cloud + Platform Eng) | G23: Stefano Pecora (Cloud + Platform Eng) | O23: =VLOOKUP(B23,'From Databricks partner portal'!E:E,1,FALSE) -> #N/A
A24: Aditya Shukla | B24: Aditya.Shukla@intuitive.cloud | C24: Completed | D24: Databricks Certified Generative AI Engineer Associate | E24: Completed on 31st May, 2025 | F24: Pritam Dodeja (AI/MlOps) | G24: Dr Navid Kalantari PhD (Data + AI) | H24: 45797 | I24: 45930 | J24: Mandatory | O24: =VLOOKUP(B24,'From Databricks partner portal'!E:E,1,FALSE) -> #N/A
A25: Darshan Bhavsar | B25: Darshan.Bhavsar@intuitive.cloud | C25: Completed | D25: Databricks Certified Generative AI Engineer Associate | E25: Completed on 13th May, 2025 | F25: Pritam Dodeja (AI/MlOps) | G25: Bhavesh Shah (Cloud Native) | H25: 45805 | I25: 45930 | J25: Mandatory | O25: =VLOOKUP(B25,'From Databricks partner portal'!E:E,1,FALSE) -> #N/A
A26: Daljit Singh | B26: Daljit.Singh@intuitive.cloud | C26: In-progress | F26: Mohammed Shabbir (App + DB Mod) | G26: Mohammed Shabbir (App + DB Mod) | J26: Mandatory | O26: =VLOOKUP(B26,'From Databricks partner portal'!E:E,1,FALSE) -> #N/A
A27: Daniel Zivkovic | B27: daniel.zivkovic@intuitive.cloud | C27: In-progress | F27: Dr Kanav Kahol PhD (Data + AI) | G27: Dr Navid Kalantari PhD (Data + AI) | J27: Mandatory | O27: =VLOOKUP(B27,'From Databricks partner portal'!E:E,1,FALSE) -> #N/A
A28: Anurag Kapatia | B28: Anurag.Kapatia@intuitive.cloud | C28: Completed | D28: Databricks Certified Data Engineer Associate | E28: Completed on 27th April, 2025 | F28: Chett Rubenstein (Data + AI) | G28: Chett Rubenstein (Data + AI) | H28: 45824 | I28: 45930 | J28: Mandatory | N28: Pending | O28: =VLOOKUP(B28,'From Databricks partner portal'!E:E,1,FALSE) -> #N/A
A29: Sachin Nakhate | B29: sachin.nakhate@intuitive.cloud | C29: Completed | D29: Databricks Certified Generative AI Engineer Associate | E29: Completed on 16th June 2025 | F29: Saksham Baru (Cloud Engineering) | G29: Stefano Pecora (Cloud + Platform Eng) | H29: 45824 | I29: 45930 | J29: Mandatory | O29: =VLOOKUP(B29,'From Databricks partner portal'!E:E,1,FALSE) -> #N/A
A30: Thamtam Pruthvi | B30: Thamtam.Pruthvi@intuitive.cloud | C30: Completed | D30: Databricks Certified Data Analyst Associate | E30: Completed on 16th June 2025 | F30: Saksham Baru (Cloud Engineering) | G30: Stefano Pecora (Cloud + Platform Eng) | H30: 45824 | I30: 45930 | J30: Mandatory | O30: =VLOOKUP(B30,'From Databricks partner portal'!E:E,1,FALSE) -> #N/A
A31: David Hammond | B31: david.hammond@intuitive.cloud | C31: In-progress | F31: Chett Rubenstein (Data + AI) | G31: Chett Rubenstein (Data + AI) | J31: Mandatory | O31: =VLOOKUP(B31,'From Databricks partner portal'!E:E,1,FALSE) -> #N/A
A32: Devangi Goswami | B32: devangi.goswami@intuitive.cloud | C32: Completed | D32: Databricks Certified Data Analyst Associate | E32: Completed on 23rd April, 2025 | F32: Vishal Kanade (Cloud Engineering) | G32: Bhavesh Shah (Cloud Native) | H32: 45825 | I32: 45930 | J32: Mandatory | O32: =VLOOKUP(B32,'From Databricks partner portal'!E:E,1,FALSE) -> #N/A
A33: Narendar Adula | B33: Narendar.Adula@intuitive.cloud | C33: Completed | D33: Databricks Certified Data Analyst Associate | E33: Complete on 28th May 2025 | F33: Saksham Baru (Cloud Engineering) | G33: Stefano Pecora (Cloud + Platform Eng) | H33: 45825 | I33: 45930 | J33: Mandatory | O33: =VLOOKUP(B33,'From Databricks partner portal'!E:E,1,FALSE) -> #N/A | P33: Asked to follow KB article
A34: Deepak Shrivastav | B34: Deepak.Shrivastav@intuitive.cloud | C34: In-progress | F34: Mohammed Shabbir (App + DB Mod) | G34: Mohammed Shabbir (App + DB Mod) | J34: Mandatory | O34: =VLOOKUP(B34,'From Databricks partner portal'!E:E,1,FALSE) -> #N/A
A35: Hemanth Reddy | B35: Hemanth.Reddy@intuitive.cloud | C35: Completed | D35: Databricks Certified Data Analyst Associate | E35: Complete on 18 th May 2025 | F35: Saksham Baru (Cloud Engineering) | G35: Dr Navid Kalantari PhD (Data + AI) | H35: 45826 | I35: 45930 | J35: Mandatory | O35: =VLOOKUP(B35,'From Databricks partner portal'!E:E,1,FALSE) -> #N/A
A36: Sundarapandi Dhanushkodi | B36: Sundarapandi.Dhanushkodi@intuitive.cloud | C36: Completed | D36: Databricks Certified Data Analyst Associate | E36: Complete on 18 th May 2025 | F36: Saksham Baru (Cloud Engineering) | G36: Stefano Pecora (Cloud + Platform Eng) | H36: 45826 | I36: 45930 | J36: Mandatory | O36: =VLOOKUP(B36,'From Databricks partner portal'!E:E,1,FALSE) -> #N/A
A37: Ashish Dudeja | B37: ashish.dudeja@intuitive.ai | C37: Completed | D37: Databricks Certified Data Engineer Associate | F37: Chett Rubenstein (Data + AI) | G37: Chett Rubenstein (Data + AI) | H37: 45830 | I37: 45930 | J37: Mandatory | O37: =VLOOKUP(B37,'From Databricks partner portal'!E:E,1,FALSE) -> #N/A
A38: Gaurav Gangwar | B38: Gaurav.Gangwar@intuitive.ai | C38: Completed | D38: Databricks Certified Data Engineer Associate | E38: Completed on 27th April, 2025 | F38: Chett Rubenstein (Data + AI) | G38: Chett Rubenstein (Data + AI) | H38: 45766 | I38: 45930 | J38: Mandatory | O38: =VLOOKUP(B38,'From Databricks partner portal'!E:E,1,FALSE) -> gaurav.gangwar@intuitive.ai
A39: Gaurav Suthar | B39: gaurav.suthar@intuitive.ai | C39: In-progress | F39: Abilash Sivakumar (Cloud + Platform Eng) | G39: Stefano Pecora (Cloud + Platform Eng) | O39: =VLOOKUP(B39,'From Databricks partner portal'!E:E,1,FALSE) -> #N/A
A40: Yaswardhan Reddy | B40: Yaswardhan.Reddy@intuitive.cloud | C40: Completed | D40: Databricks Certified Data Analyst Associate | F40: Saksham Baru (Cloud Engineering) | G40: Stefano Pecora (Cloud + Platform Eng) | H40: 45878 | I40: 45930 | J40: Mandatory | O40: =VLOOKUP(B40,'From Databricks partner portal'!E:E,1,FALSE) -> #N/A | P40: Asked to follow KB article
...

Sheet Sheet1
A1: Name | B1: Email ID | C1: Completed | D1: Cert Type
A2: Keval Hingu | B2: Keval.Hingu@intuitive.cloud | C2: Completed | D2: Databricks Certified Data Analyst Associate
A3: Prem Gandhi | B3: Prem.Gandhi@intuitive.cloud | C3: Completed | D3: Databricks Certified Machine Learning Associate
A4: Aniket Purohit | B4: Aniket.Purohit@intuitive.cloud | C4: Completed | D4: Databricks Certified Generative AI Engineer Associate
A5: Divya Mahesh | B5: Divya.Mahesh@intuitive.cloud | C5: Completed | D5: Databricks Certified Generative AI Engineer Associate
A6: Ajay Shridhar Giri | B6: Ajay.Giri@intuitive.cloud | C6: Completed | D6: Databricks Certified Data Analyst Associate
A7: Dinesh Verma | B7: dinesh.verma@intuitive.cloud | C7: Completed | D7: Databricks Certified Generative AI Engineer Associate
A8: Ravindra Malpute | B8: Ravindra.Malpute@intuitive.cloud | C8: Completed | D8: Databricks Certified Generative AI Engineer Associate
A9: Saumil Shah | B9: Saumil.Shah@intuitive.cloud | C9: Completed | D9: Databricks Certified Data Analyst Associate
A10: Abhijeet Patil | B10: Abhijeet.Patil@intuitive.cloud | C10: Completed | D10: Databricks Certified Data Analyst Associate
A11: Aditya Shukla | B11: Aditya.Shukla@intuitive.cloud | C11: Completed | D11: Databricks Certified Generative AI Engineer Associate
A12: Darshan Bhavsar | B12: Darshan.Bhavsar@intuitive.cloud | C12: Completed | D12: Databricks Certified Generative AI Engineer Associate
... A56: Sharath Rao | B56: sharath.rao@intuitive.cloud | C56: Completed | D56: Databricks Certified Data Analyst Associate
A57: Vishal Bhartdwaj | C57: Completed | D57: Databricks Certified Data Analyst Associate
A58: Karuna Katikala | B58: karuna.katikala@intuitive.ai | C58: Completed | D58: Databricks Certified Data Engineer Associate
A59: Hetul Patel | B59: Hetul.Patel@intuitive.cloud | C59: Completed | D59: Databricks Certified Generative AI Engineer Associate
A60: Kishore Gajula | B60: kishore.gajula@intuitive.cloud | C60: Completed | D60: Databricks Certified Generative AI Engineer Associate
A61: Milind Dhake | B61: milind.dhake@intuitive.cloud | C61: Completed | D61: Databricks Certified Generative AI Engineer Associate

Sheet From Databricks partner portal
A1: AS AT 2026-04-10
A2: # | B2: Category | C2: Course | D2: Date | E2: Email | F2: Points
A3: 14 | B3: Technical Certified | C3: Databricks Certified Data Engineer Associate | D3: 45844 | E3: - | F3: 0.5
A4: 11 | B4: Technical Certified | C4: Databricks Certified Data Analyst Associate | D4: 46057 | E4: abdul.haleem@intuitive.ai | F4: 0.5
A5: 9 | B5: Sales Badged | C5: Academy Accreditation - Databricks Fundamentals | D5: 46050 | E5: abdul.haleem@intuitive.ai | F5: 0.25
A6: 46 | B6: Technical Certified | C6: Databricks Certified Data Analyst Associate | D6: 46019 | E6: aditya.desai@intuitive.ai | F6: 0.5
A7: 17 | B7: Sales Badged | C7: Academy Accreditation - Generative AI Fundamentals | D7: 46056 | E7: akshay.agarwal@intuitive.ai | F7: 0.25
A8: 48 | B8: Sales Badged | C8: Academy Accreditation - Databricks Fundamentals | D8: 46037 | E8: amrith.samuel@intuitive.ai | F8: 0.25
A9: 40 | B9: Technical Certified | C9: Databricks Certified Data Analyst Associate | D9: 45985 | E9: aryan.vasudev@intuitive.ai | F9: 0.5 | G9: =COUNTIF(E:E,E9) -> 1
A10: 13 | B10: Technical Certified | C10: Databricks Certified Data Analyst Associate | D10: 46026 | E10: ayan.abbas@intuitive.ai | F10: 0.5 | G10: =COUNTIF(E:E,E10) -> 1
A11: 8 | B11: Technical Certified | C11: Databricks Certified Data Analyst Associate | D11: 45979 | E11: bhumi.patel@intuitive.ai | F11: 0.5 | G11: =COUNTIF(E:E,E11) -> 1
A12: 51 | B12: Technical Certified | C12: Databricks Certified Data Analyst Associate | D12: 46047 | E12: chaitanya.baweja@intuitive.ai | F12: 0.5 | G12: =COUNTIF(E:E,E12) -> 1
A13: 33 | B13: Technical Certified | C13: Databricks Certified Data Analyst Associate | D13: 46031 | E13: darshan.rajyaguru@intuitive.ai | F13: 0.5 | G13: =COUNTIF(E:E,E13) -> 1
A14: 57 | B14: Sales Badged | C14: Partner Training - Data Intelligence Platform Whiteboard | D14: 46094 | E14: david.hammond@intuitive.ai | F14: 0.25 | G14: =COUNTIF(E:E,E14) -> 2
A15: 56 | B15: Sales Badged | C15: Partner Training - Azure Databricks Foundations | D15: 46097 | E15: david.hammond@intuitive.ai | F15: 0.25 | G15: =COUNTIF(E:E,E15) -> 2
A16: 27 | B16: Sales Badged | C16: Partner Training - Gen AI & LLM on Databricks | D16: 46084 | E16: debrup.mondal@intuitive.ai | F16: 0.25 | G16: =COUNTIF(E:E,E16) -> 3
A17: 25 | B17: Sales Badged | C17: Partner Training - Advantages of Gen AI with Data Intelligence | D17: 46116 | E17: debrup.mondal@intuitive.ai | F17: 0.25 | G17: =COUNTIF(E:E,E17) -> 3
A18: 26 | B18: Sales Badged | C18: Partner Training - 2025 Data + AI Summit Product Announcement Enablement for Partners | D18: 46084 | E18: debrup.mondal@intuitive.ai | F18: 0.25 | G18: =COUNTIF(E:E,E18) -> 3
A19: 43 | B19: Technical Certified | C19: Databricks Certified Data Analyst Associate | D19: 46079 | E19: dhruv.maradiya@intuitive.ai | F19: 0.5 | G19: =COUNTIF(E:E,E19) -> 1
A20: 2 | B20: Technical Certified | C20: Databricks Certified Data Analyst Associate | D20: 46027 | E20: garret.fernandez@intuitive.ai | F20: 0.5 | G20: =COUNTIF(E:E,E20) -> 1
... A61: 31 | B61: Technical Certified | C61: Databricks Certified Data Analyst Associate | D61: 46045 | E61: yuktha.pulukkul@intuitive.ai | F61: 0.5 | G61: =COUNTIF(E:E,E61) -> 1
F63: =SUM(F3:F62) -> 25.5

Sheet Registration & Status
A1: Name | B1: Designation | C1: Reporting Manager | D1: Status
A2: Dhruvi Soni | B2: Networking / Cyber Security Engg | C2: Mukesh Kumar (Cloud NetSec)
A3: Darshil Chocha | B3: Networking / Cyber Security Engg | C3: Mukesh Kumar (Cloud NetSec)
A4: Arnav Bansal | B4: Networking / Cyber Security Engg | C4: Mukesh Kumar (Cloud NetSec)
A5: Satvik Sharma | B5: Networking / Cyber Security Engg | C5: Mukesh Kumar (Cloud NetSec)
A6: Het Parikh | B6: Networking / Cyber Security Engg | C6: Mukesh Kumar (Cloud NetSec)
A7: Tanvi Sontakke | B7: Networking / Cyber Security Engg | C7: Mukesh Kumar (Cloud NetSec)
A8: Ankit Mukherjee | B8: Networking / Cyber Security Engg | C8: Mukesh Kumar (Cloud NetSec)
A9: Bhumi Patel | B9: AI/ML Engineer | C9: Bhavesh Shah (Cloud Native) | D9: Exam Cleared
A10: Vishal Mehta | B10: AI/ML Engineer | C10: Bhavesh Shah (Cloud Native) | D10: Exam Cleared
A11: Prachi Desai | B11: AI/ML Engineer | C11: Bhavesh Shah (Cloud Native) | D11: Exam Cleared
A12: Smit Gandhi | B12: AI/ML Engineer | C12: Bhavesh Shah (Cloud Native) | D12: Exam Cleared
A13: Vasu Bhimani | B13: Cloud Engineer | C13: Bhavesh Shah (Cloud Native)
A14: Tisha Patel | B14: Cloud Engineer | C14: Bhavesh Shah (Cloud Native) | D14: Schedule on 30th
A15: Rushi Kardani | B15: Database Engineer | C15: Bhavesh Shah (Cloud Native) | D15: Exam cleared
A16: Pearl Jatonia | B16: AI/ML Engineer | C16: Bhavesh Shah (Cloud Native)
A17: Ayan Abbas | B17: AI/ML Engineer | C17: Bhavesh Shah (Cloud Native) | D17: Schedule
A18: Vishnu Burkhawala | B18: Application Developer | C18: Bhavesh Shah (Cloud Native) | D18: Schedule on 28th
A19: Vraj Modi | B19: Application Developer | C19: Bhavesh Shah (Cloud Native) | D19: Exam Cleared
A20: Sumit Mishra | B20: Application Developer | C20: Bhavesh Shah (Cloud Native) | D20: Schedule on 28th
A21: Garret Fernandez | B21: DataBase Engineer | C21: Bhavesh Shah (Cloud Native) | D21: Schedule on 4th
A22: Harsh Kharwar | B22: AI/ML Engineer | C22: Bhavesh Shah (Cloud Native) | D22: Schedule on 30th
A23: Tanvi Sontakke | B23: Networking / Cyber Security Engg | C23: Mukesh Kumar (Cloud NetSec)
A24: Chaitanya Baweja | B24: Project Management Office | C24: Mohammed Yakhoob (PMO)
A25: Gourab Banerjee | B25: Project Management Office | C25: Mohammed Yakhoob (PMO)
A26: Yuktha Pulukkul | B26: Project Management Office | C26: Mohammed Yakhoob (PMO)
A27: Shantanu Hiwrale | B27: AI/ML Engineer | C27: Bhavesh Shah (Cloud Native) | D27: Exam Cleared
A28: Srushti Moghe | B28: Database Engineer | C28: Bhavesh Shah (Cloud Native) | D28: Exam Cleared
A29: Vishal | B29: Software Developer | C29: Bhavesh Shah (Cloud Native) | D29: Schedule on 3rd jan
A30: Suyash Srivastava | B30: Software Developer | C30: Bhavesh Shah (Cloud Native) | D30: Exam Cleared
A31: Aryan Vasudeva | B31: Platform Engineer | C31: Bhavesh Shah (Cloud Native) | D31: Exam Cleared
A32: Janhvi Kurkure | B32: Software Developer | C32: Bhavesh Shah (Cloud Native) | D32: Exam Cleared
A33: Darshan Rajyaguru | B33: Platform Engineer | C33: Bhavesh Shah (Cloud Native)
A34: Jigarkumar Bhoye | B34: Cloud & DevOps Engineer | C34: Bhavesh Shah (Cloud Native)
A35: Pundrik Shayta | B35: Software Developer | C35: Bhavesh Shah (Cloud Native) | D35: Exam Cleared
A36: Rahul Morabiya | B36: Cloud & DevOps Engineer | C36: Bhavesh Shah (Cloud Native) | D36: Schedule
A37: Shourya Nahar | B37: Software Developer | C37: Bhavesh Shah (Cloud Native) | D37: Exam Cleared
A38: Parth Vadodaria | B38: Software Developer | C38: Bhavesh Shah (Cloud Native) | D38: Exam Cleared
A39: Aditya Desai | B39: Cloud & DevOps Engineer | C39: Bhavesh Shah (Cloud Native) | D39: Exam Cleared
A40: Malhar Prajapati | B40: Data Engineer & AI ML | C40: Bhavesh Shah (Cloud Native) | D40: Exam Cleared
...

Sheet Accreditations
A1: Name | B1: Email ID | C1: Completed | D1: Cert Type | E1: Comments | F1: Reports To | G1: Practice Director
A2: Lisa Sikkema | B2: lisa.sikkema@intuitive.cloud | C2: Completed | D2: Advantages of Data & AI Governance | F2: Chett Rubenstein (Data) | G2: Chett Rubenstein (Data)

Sheet Dupes or Former Employees

Sheet Sheet2
A8: Not Started
A9: In-progress
A10: Completed
A16: Databricks Certified Data Analyst Associate
A17: Databricks Certified Data Engineer Associate
A18: Databricks Certified Machine Learning Associate
A19: Databricks Certified Data Engineer Professional
A20: Databricks Certified Machine Learning Professional
A21: Databricks Certified Generative AI Engineer Associate
A22: Databricks Certified Associate Developer for Apache Spark

Sheet Resources
A1: Resource Type | B1: Course Name
A2: Udemy
A3: Udemy
A4: Udemy
